Workbook

Sheet 00_Leeme
A1: Laboratorio: Mundiales 2018, 2022 y 2026
A2: Preparación de datos con Excel y Python; transición al análisis supervisado. Se utiliza exclusivamente la fase de grupos para mantener comparable la etapa deportiva.
A5: Ruta de trabajo
A6: Paso | B6: Actividad | C6: Qué debe ocurrir | D6: Herramienta
A7: 1 | B7: Perfilar | C7: Revisar estructura, tipos, vacíos, valores extraños y duplicados. | D7: Excel
A8: 2 | B8: Definir reglas | C8: Documentar qué se corregirá y con qué evidencia. | D8: Bitácora
A9: 3 | B9: Limpiar | C9: Normalizar columnas, equipos, fechas, grupos, goles y booleanos. | D9: Excel / Python
A10: 4 | B10: Validar | C10: Comprobar conteos, unicidad, rangos y consistencia. | D10: Pruebas
A11: 5 | B11: Comparar | C11: Usar tasas y promedios; no solo totales. | D11: Excel
A12: 6 | B12: Modelar | C12: Construir variables conocidas antes del partido. | D12: Python
A13: 7 | B13: Evaluar | C13: Comparar árbol, línea base y experimento con fuga. | D13: Python
A16: Resultados de control después de limpiar
A17: Mundial | B17: Partidos | C17: Goles | D17: Goles/partido | E17: Empates | F17: Cobertura
A18: 2018 | B18: 48 | C18: 122 | D18: 2.5417 | E18: 9 | F18: 32 equipos / 8 grupos
A19: 2022 | B19: 48 | C19: 120 | D19: 2.5 | E19: 10 | F19: 32 equipos / 8 grupos
A20: 2026 | B20: 72 | C20: 215 | D20: 2.9861 | E20: 20 | F20: 48 equipos / 12 grupos
A23: Advertencia: los datos sucios contienen errores deliberados. No elimines registros ni imputes valores sin justificar la decisión. El objetivo no es únicamente obtener una tabla limpia, sino construir un proceso reproducible y explicar por qué cada transformación es necesaria.

Sheet 01_Diccionario
A1: Diccionario de la base integrada
A2: Campos mínimos esperados después de unificar los tres archivos.
A5: Campo | B5: Tipo esperado | C5: Descripción | D5: Ejemplo | E5: Derivado
A6: partido_id | B6: Texto | C6: Identificador único del encuentro. | D6: M-2018-001 | E6: No
A7: mundial | B7: Entero | C7: Año del torneo. | D7: 2018 | E7: No
A8: fase | B8: Categoría | C8: Etapa del torneo; en el kit siempre será Fase de grupos. | D8: Fase de grupos | E8: No
A9: grupo | B9: Categoría | C9: Grupo A-L. | D9: A | E9: No
A10: jornada | B10: Entero | C10: Jornada 1, 2 o 3. | D10: 1 | E10: No
A11: fecha | B11: Fecha | C11: Fecha real del partido. | D11: 2018-06-14 | E11: No
A12: equipo_local | B12: Texto | C12: Nombre canónico del equipo local. | D12: Russia | E12: No
A13: equipo_visitante | B13: Texto | C13: Nombre canónico del equipo visitante. | D13: Saudi Arabia | E13: No
A14: goles_local | B14: Entero | C14: Goles del equipo local; debe ser mayor o igual que cero. | D14: 5 | E14: No
A15: goles_visitante | B15: Entero | C15: Goles del visitante; debe ser mayor o igual que cero. | D15: 0 | E15: No
A16: marcador | B16: Derivado | C16: Texto goles_local-goles_visitante. | D16: 5-0 | E16: Sí
A17: resultado_local | B17: Derivado | C17: Gana, Empata o Pierde desde la perspectiva local. | D17: Gana | E17: Sí
A18: local_es_anfitrion | B18: Booleano | C18: Indica si el local pertenece a un país anfitrión. | D18: =TRUE() -> TRUE | E18: No
A19: visitante_es_anfitrion | B19: Booleano | C19: Indica si el visitante pertenece a un país anfitrión. | D19: =FALSE() -> FALSE | E19: No
A20: goles_totales | B20: Derivado | C20: Suma de los goles del partido. | D20: 5 | E20: Sí
A21: diferencia_goles | B21: Derivado | C21: Goles local menos goles visitante. | D21: 5 | E21: Sí
A22: puntos_local | B22: Derivado | C22: 3 por victoria, 1 por empate y 0 por derrota. | D22: 3 | E22: Sí
A23: puntos_visitante | B23: Derivado | C23: 3 por victoria, 1 por empate y 0 por derrota. | D23: 0 | E23: Sí
A24: fuente | B24: URL | C24: Origen del dato limpio. | D24: https://... | E24: No

Sheet 02_Catalogo_Equipos
A1: Catálogo de equipos
A2: Utiliza la variante para buscar y devolver el nombre canónico. Conserva los acentos en el nombre que se mostrará.
A5: Variante | B5: Nombre canónico | C5: Código | D5: Observación del equipo
A6: Algeria | B6: Algeria | C6: DZA
A7: Argentina | B7: Argentina | C7: ARG
A8: Australia | B8: Australia | C8: AUS
A9: Austria | B9: Austria | C9: AUT
A10: Belgium | B10: Belgium | C10: BEL
A11: Bosnia | B11: Bosnia and Herzegovina | C11: BIH
A12: Bosnia & Herzegovina | B12: Bosnia and Herzegovina | C12: BIH
A13: Bosnia and Herzegovina | B13: Bosnia and Herzegovina | C13: BIH
A14: Bosnia-Herzegovina | B14: Bosnia and Herzegovina | C14: BIH
A15: Brasil | B15: Brazil | C15: BRA
A16: Brazil | B16: Brazil | C16: BRA
A17: Cameroon | B17: Cameroon | C17: CMR
... A54: Japan | B54: Japan | C54: JPN
A55: Jordan | B55: Jordan
A56: Mexico | B56: Mexico | C56: MEX
A57: México | B57: Mexico | C57: MEX
A58: Morocco | B58: Morocco | C58: MAR
A59: Holland | B59: Netherlands | C59: NLD
A60: Netherlands | B60: Netherlands | C60: NLD
A61: The Netherlands | B61: Netherlands | C61: NLD
A62: New Zealand | B62: New Zealand | C62: NZL
A63: New-Zealand | B63: New Zealand | C63: NZL
A64: Nigeria | B64: Nigeria | C64: NGA
A65: Norway | B65: Norway | C65: NOR
A66: Panama | B66: Panama | C66: PAN
A67: Paraguay | B67: Paraguay | C67: PRY
... A98: Uruguay | B98: Uruguay | C98: URY
A99: Uzbekistan | B99: Uzbekistan
A100: Wales | B100: Wales | C100: WAL

Sheet 03_Sucio_2018
A1: 03 Sucio 2018
A2: Datos deliberadamente alterados: revisa formatos, nulos, conflictos y duplicados.
A5: ID Partido | B5: Año | C5: Fase | D5: Grupo | E5: Jornada | F5: Fecha | G5: Hora | H5: Equipo Local | I5: Equipo Visitante | J5: Goles Local | K5: Goles Visitante | L5: Marcador | M5: Anfitrión Local | N5: Estadio | O5: Ciudad | P5: Fuente
A6: M-2018-01 | B6: 2018 | C6: Fase de grupos | D6: Grupo A | E6: 1 | F6: 2018-06-14 | G6: 18:00 | H6: russia | I6: KSA | J6: 5 goles | L6: 5-0 | M6: Sí | N6: Luzhniki Stadium | O6: Moscow | P6: https://github.com/jfjelstul/worldcup
A7: M-2018-02 | B7: 2018 | C7: GROUP STAGE | D7: A | E7: 1 | F7: 15/06/2018 | G7: 17:00 | H7: Egypt | I7: Uruguay | J7: 0 | K7: 1 | L7: 0–1 | M7: 0 | N7: Central Stadium | O7: Yekaterinburg | P7: https://github.com/jfjelstul/worldcup
A8: M-2018-03 | B8: 2018 | C8: grupos | D8: group-b | E8: 1 | F8: 06/15/2018 | G8: 18:00 | H8: Morocco | I8: Iran, I.R. | J8: 0 | K8: 1 | L8: 0 : 1 | M8: FALSE | N8: Krestovsky Stadium | O8: Saint Petersburg | P8: https://github.com/jfjelstul/worldcup
A9: M-2018-04 | B9: 2018 | C9: 1ra fase | D9: Grupo B | E9: 1 | F9: 15-06-18 | G9: 21:00 | H9: Portugal | I9: España | J9: 3 | K9: 3 | L9: 3 x 3 | M9: no | N9: Fisht Olympic Stadium | O9: Sochi | P9: https://github.com/jfjelstul/worldcup
A10: M-2018-05 | B10: 2018 | C10: Fase de grupos | D10: C | E10: 1 | F10: Jun 16, 2018 | G10: 13:00 | H10: France | I10: Australia | J10: 2 | K10: 1 | L10: 2—1 | M10: No | N10: Kazan Arena | O10: Kazan | P10: https://github.com/jfjelstul/worldcup
A11: M-2018-06 | B11: 2018 | C11: GROUP STAGE | D11: group-d | E11: 1 | F11: 2018-06-16 | G11: 16:00 | H11: Argentina | I11: Iceland | J11: 1 | K11: 1 | L11: 1-1 | M11: 0 | N11: Otkritie Arena | O11: Moscow | P11: https://github.com/jfjelstul/worldcup
A12: M-2018-07 | B12: 2018 | C12: grupos | D12: Grupo C | E12: 1 | F12: 16/06/2018 | G12: 19:00 | H12: Peru | I12: Denmark | J12: 0 | K12: 1 | L12: 0–1 | M12: FALSE | N12: Mordovia Arena | O12: Saransk | P12: https://github.com/jfjelstul/worldcup
A13: M-2018-08 | B13: 2018 | C13: 1ra fase | D13: D | E13: 1 | F13: 06/16/2018 | G13: 21:00 | H13: Croatia | I13: Nigeria | J13: 2 | K13: 0 | L13: 2 : 0 | M13: no | N13: Kaliningrad Stadium | O13: Kaliningrad | P13: https://github.com/jfjelstul/worldcup
A14: M-2018-09 | B14: 2018 | C14: Fase de grupos | D14: group-e | E14: 1 | F14: 17-06-18 | G14: 16:00 | H14: Costa Rica | I14: Serbia | J14: 0 | K14: 1 | L14: 0 x 1 | M14: No | N14: Samara Arena | O14: Samara | P14: https://github.com/jfjelstul/worldcup
A15: M-2018-10 | B15: 2018 | C15: GROUP STAGE | E15: 1 | F15: Jun 17, 2018 | G15: 18:00 | H15: Germany | I15: Mexico | J15: 0 | K15: 1 | L15: 0—1 | M15: 0 | N15: Luzhniki Stadium | O15: Moscow | P15: https://github.com/jfjelstul/worldcup
A16: M-2018-11 | B16: 2018 | C16: grupos | D16: E | E16: 1 | F16: 2018-06-17 | G16: 21:00 | H16: Brasil | I16: Switzerland | J16: 1 | K16: 1 | L16: 1-1 | M16: FALSE | N16: Rostov Arena | O16: Rostov-on-Don | P16: https://github.com/jfjelstul/worldcup
A17: M-2018-12 | B17: 2018 | C17: 1ra fase | D17: group-f | E17: 1 | F17: 18/06/2018 | G17: 15:00 | H17: Sweden | I17: Rep. of Korea | J17: 1 | K17: 0 | L17: 1–0 | M17: no | N17: Nizhny Novgorod Stadium | O17: Nizhny Novgorod | P17: https://github.com/jfjelstul/worldcup
A18: M-2018-13 | B18: 2018 | C18: Fase de grupos | D18: Grupo G | E18: 1 | F18: 06/18/2018 | G18: 18:00 | H18: Belgium | I18: Panama | J18: 3 | K18: 0 | L18: 3 : 0 | M18: No | N18: Fisht Olympic Stadium | O18: Sochi | P18: https://github.com/jfjelstul/worldcup
A19: M-2018-14 | B19: 2018 | C19: GROUP STAGE | D19: G | E19: 1 | F19: 18-06-18 | G19: 21:00 | H19: Tunisia | I19: England | J19: 1 goles | K19: 2 | L19: 1 x 2 | M19: 0 | N19: Volgograd Arena | O19: Volgograd | P19: https://github.com/jfjelstul/worldcup
A20: M-2018-15 | B20: 2018 | C20: grupos | D20: group-h | E20: 1 | F20: Jun 19, 2018 | G20: 15:00 | H20: Colombia | I20: JAPAN | J20: 1 | K20: 2 | L20: 1—2 | M20: FALSE | N20: Mordovia Arena | O20: Saransk | P20: https://github.com/jfjelstul/worldcup
A21: M-2018-16 | B21: 2018 | C21: 1ra fase | D21: Grupo H | E21: 1 | F21: 2018-06-19 | G21: 18:00 | H21: Poland | I21: Senegal | J21: 1 | K21: 2 | M21: no | N21: Otkritie Arena | O21: Moscow | P21: https://github.com/jfjelstul/worldcup
A22: M-2018-17 | B22: 2018 | C22: Fase de grupos | D22: A | E22: 2 | F22: 19/06/2018 | G22: 21:00 | H22: Russia | I22: Egypt | J22: 3 | K22: 1 | L22: 3–1 | M22: Sí | N22: Krestovsky Stadium | O22: Saint Petersburg | P22: https://github.com/jfjelstul/worldcup
A23: M-2018-18 | B23: 2018 | C23: GROUP STAGE | D23: group-b | E23: 2 | F23: 06/20/2018 | G23: 15:00 | H23: PORTUGAL | I23: Morocco | J23: 1 | K23: 0 | L23: 1 : 0 | M23: 0 | N23: Luzhniki Stadium | O23: Moscow | P23: https://github.com/jfjelstul/worldcup
A24: M-2018-19 | B24: 2018 | C24: grupos | D24: Grupo A | E24: 2 | F24: 20-06-18 | G24: 18:00 | H24: Uruguay | I24: KSA | J24: 1 | K24: 0 | L24: 1 x 0 | M24: FALSE | N24: Rostov Arena | O24: Rostov-on-Don | P24: https://github.com/jfjelstul/worldcup
A25: M-2018-20 | B25: 2018 | C25: 1ra fase | D25: B | E25: 2 | F25: Jun 20, 2018 | G25: 21:00 | H25: Iran | I25: España | J25: 0 | L25: 0—1 | M25: no | N25: Kazan Arena | O25: Kazan | P25: https://github.com/jfjelstul/worldcup
A26: M-2018-21 | B26: 2018 | C26: Fase de grupos | D26: group-c | E26: 2 | F26: 2018-06-21 | G26: 16:00 | H26: Denmark | I26: australia | J26: 1 | K26: 1 | L26: 1-1 | M26: No | N26: Samara Arena | O26: Samara | P26: https://github.com/jfjelstul/worldcup
A27: M-2018-22 | B27: 2018 | C27: GROUP STAGE | D27: Grupo C | E27: 2 | F27: 21/06/2018 | G27: 20:00 | H27: France | I27: Peru | J27: 1 | K27: 0 | L27: 1–0 | M27: 0 | N27: Central Stadium | O27: Yekaterinburg | P27: https://github.com/jfjelstul/worldcup
A28: M-2018-23 | B28: 2018 | C28: grupos | D28: D | E28: 2 | F28: 06/21/2018 | G28: 21:00 | H28: Argentina | I28: Croatia | J28: -1 | K28: 3 | L28: 0 : 3 | M28: FALSE | N28: Nizhny Novgorod Stadium | O28: Nizhny Novgorod | P28: https://github.com/jfjelstul/worldcup
A29: M-2018-24 | B29: 2018 | C29: 1ra fase | D29: group-e | E29: 2 | F29: 22-06-18 | G29: 15:00 | H29: brazil | I29: Costa Rica | J29: 2 | K29: 0 | L29: 2 x 0 | M29: no | N29: Krestovsky Stadium | O29: Saint Petersburg | P29: https://github.com/jfjelstul/worldcup
A30: M-2018-25 | B30: 2018 | C30: Fase de grupos | D30: Grupo D | E30: 2 | F30: Jun 22, 2018 | G30: 18:00 | H30: Nigeria | I30: Iceland | J30: 2 | K30: 0 | L30: 2—0 | M30: No | N30: Volgograd Arena | O30: Volgograd | P30: https://github.com/jfjelstul/worldcup
A31: M-2018-26 | B31: 2018 | C31: GROUP STAGE | D31: E | E31: 2 | F31: 2018-06-22 | G31: 20:00 | H31: Serbia | I31: Suisse | J31: 1 | K31: 2 | L31: 1-2 | M31: 0 | N31: Kaliningrad Stadium | O31: Kaliningrad | P31: https://github.com/jfjelstul/worldcup
A32: M-2018-27 | B32: 2018 | C32: grupos | D32: group-g | E32: 2 | F32: 23/06/2018 | G32: 15:00 | H32: Belgium | I32: Tunisia | J32: 5 goles | K32: 2 | L32: 5–2 | M32: FALSE | N32: Otkritie Arena | O32: Moscow | P32: https://github.com/jfjelstul/worldcup
A33: M-2018-28 | B33: 2018 | C33: 1ra fase | D33: Grupo F | E33: 2 | F33: 06/23/2018 | G33: 18:00 | H33: South Korea | I33: Mexico | J33: 1 | K33: 2 | L33: 1 : 2 | M33: no | N33: Rostov Arena | O33: Rostov-on-Don | P33: https://github.com/jfjelstul/worldcup
A34: M-2018-29 | B34: 2018 | C34: Fase de grupos | D34: F | E34: 2 | F34: 23-06-18 | G34: 21:00 | H34: Deutschland | I34: Sweden | J34: 2 | K34: 1 | L34: 2 x 1 | M34: No | N34: Fisht Olympic Stadium | O34: Sochi | P34: https://github.com/jfjelstul/worldcup
A35: M-2018-30 | B35: 2018 | C35: GROUP STAGE | D35: group-g | E35: 2 | F35: Jun 24, 2018 | G35: 15:00 | H35: England | I35: Panama | J35: 6 | K35: 1 | L35: 6—1 | M35: 0 | N35: Nizhny Novgorod Stadium | O35: Nizhny Novgorod | P35: https://github.com/jfjelstul/worldcup
A36: M-2018-31 | B36: 2018 | C36: grupos | D36: Grupo H | E36: 2 | F36: 2018-06-24 | G36: 20:00 | H36: Japan | I36: Senegal | J36: 2 | K36: 2 | L36: 2-2 | M36: FALSE | N36: Central Stadium | O36: Yekaterinburg | P36: https://github.com/jfjelstul/worldcup
A37: M-2018-32 | B37: 2018 | C37: 1ra fase | D37: s/d | E37: 2 | F37: 24/06/2018 | G37: 21:00 | H37: Poland | I37: COLOMBIA | J37: 0 | K37: 3 | L37: 0–3 | M37: no | N37: Kazan Arena | O37: Kazan | P37: https://github.com/jfjelstul/worldcup
... A43: M-2018-38 | B43: 2018 | C43: GROUP STAGE | D43: C | E43: 3 | F43: 06/26/2018 | G43: 17:00 | H43: Denmark | I43: France | J43: 0 | K43: 0 | L43: 0 : 0 | M43: 0 | N43: Luzhniki Stadium | O43: Moscow | P43: https://github.com/jfjelstul/worldcup
A44: M-2018-39 | B44: 2018 | C44: grupos | D44: group-d | E44: 3 | F44: 26-06-18 | G44: 21:00 | H44: Iceland | I44: Croatia | J44: 1 | L44: 1 x 2 | M44: FALSE | N44: Rostov Arena | O44: Rostov-on-Don | P44: https://github.com/jfjelstul/worldcup
A45: M-2018-40 | B45: 2018 | C45: 1ra fase | D45: Grupo D | E45: 3 | F45: Jun 26, 2018 | G45: 21:00 | H45: Nigeria | I45: Argentina | J45: 1 goles | K45: 2 | L45: 1—2 | M45: no | N45: Krestovsky Stadium | O45: Saint Petersburg | P45: https://github.com/jfjelstul/worldcup
A46: M-2018-41 | B46: 2018 | C46: Fase de grupos | D46: F | E46: 3 | F46: 2018-06-27 | G46: 17:00 | H46: Korea Rep. | I46: Germany | J46: 2 | K46: 0 | L46: 2-0 | M46: No | N46: Kazan Arena | O46: Kazan | P46: https://github.com/jfjelstul/worldcup
A47: M-2018-42 | B47: 2018 | C47: GROUP STAGE | D47: group-f | E47: 3 | F47: 27/06/2018 | G47: 19:00 | H47: México | I47: Sweden | J47: 0 | K47: 3 | L47: 0–3 | M47: 0 | N47: Central Stadium | O47: Yekaterinburg | P47: https://github.com/jfjelstul/worldcup
...

Sheet 04_Sucio_2022
A1: 04 Sucio 2022
A2: El esquema y los nombres de columnas no son iguales a 2018.
A5: match_id | B5: WorldCup | C5: stage | D5: group_name | E5: match_day | F5: date | G5: local | H5: visitor | I5: home_score | J5: away_score | K5: score_text | L5: home_host | M5: venue | N5: city_name | O5: comentario | P5: source_url
A6: M-2022-01 | B6: 2022 | C6: group | D6: Group A | E6: 1 | F6: 2022-11-20 | G6: Qatar | H6: Ecuador | I6: N/A | J6: 2 | K6: 0 : 2 | L6: 1 | M6: Al Bayt Stadium | N6: Al Khor | O6: ok | P6: https://github.com/jfjelstul/worldcup
A7: M-2022-02 | B7: 2022 | C7: Group Stage | D7: B | E7: 1 | F7: 21/11/2022 | G7: England | H7: IR Iran | I7: 6 | J7: 2 | K7: 6 x 2 | L7: FALSE | M7: Khalifa International Stadium | N7: Al Rayyan | P7: https://github.com/jfjelstul/worldcup
A8: M-2022-03 | B8: 2022 | C8: Fase grupos | D8: Grupo A | E8: 1 | F8: 11/21/2022 | G8: Senegal | H8: Netherlands | I8: 0 | J8: 2 | K8: 0—2 | L8: no | M8: Al Thumama Stadium | N8: Doha | O8: revisar | P8: https://github.com/jfjelstul/worldcup
A9: M-2022-04 | B9: 2022 | C9: group | D9: B | E9: 1 | F9: 21-11-22 | G9: United States | H9: Wales | I9: 1 | J9: 1 | K9: 1-1 | L9: No | M9: Ahmad bin Ali Stadium | N9: Al Rayyan | O9: dato importado | P9: https://github.com/jfjelstul/worldcup
A10: M-2022-05 | B10: 2022 | C10: Group Stage | D10: Group C | E10: 1 | F10: Nov 22, 2022 | G10: Argentina | H10: KSA | I10: 1 | J10: 2 | K10: 1–2 | L10: 0 | M10: Lusail Stadium | N10: Lusail | O10: ok | P10: https://github.com/jfjelstul/worldcup
A11: M-2022-06 | B11: 2022 | C11: Fase grupos | D11: D | E11: 1 | F11: 2022-11-22 | G11: Denmark | H11: Tunisia | I11: 0 | J11: 0 | K11: 0 : 0 | L11: FALSE | M11: Education City Stadium | N11: Al Rayyan | P11: https://github.com/jfjelstul/worldcup
A12: M-2022-07 | B12: 2022 | C12: group | D12: Grupo C | E12: 1 | F12: 22/11/2022 | G12: México | H12: Poland | I12: 0 | J12: 0 | K12: 0 x 0 | L12: no | M12: Stadium 974 | N12: Doha | O12: revisar | P12: https://github.com/jfjelstul/worldcup
A13: M-2022-08 | B13: 2022 | C13: Group Stage | D13: D | E13: 1 | F13: 11/22/2022 | G13: France | H13: Australia | I13: 4 | J13: 1 | K13: 4—1 | L13: No | M13: Al Janoub Stadium | N13: Al Wakrah | O13: dato importado | P13: https://github.com/jfjelstul/worldcup
A14: M-2022-09 | B14: 2022 | C14: Fase grupos | D14: Group F | E14: 1 | F14: 23-11-22 | G14: Morocco | H14: Croatia | I14: 0 | J14: 0 | K14: sin dato | L14: 0 | M14: Al Bayt Stadium | N14: Al Khor | O14: ok | P14: https://github.com/jfjelstul/worldcup
A15: M-2022-10 | B15: 2022 | C15: group | D15: E | E15: 1 | F15: Nov 23, 2022 | G15: Deutschland | H15: JAPAN | I15: 1 | J15: 2 | K15: 1–2 | L15: FALSE | M15: Khalifa International Stadium | N15: Al Rayyan | P15: https://github.com/jfjelstul/worldcup
A16: M-2022-11 | B16: 2022 | C16: Group Stage | D16: Grupo E | E16: 1 | F16: 2022-11-23 | G16: Spain | H16: Costa Rica | I16: 7 | J16: 0 | K16: 7 : 0 | L16: no | M16: Al Thumama Stadium | N16: Doha | O16: revisar | P16: https://github.com/jfjelstul/worldcup
A17: M-2022-12 | B17: 2022 | C17: Fase grupos | E17: 1 | F17: 23/11/2022 | G17: Belgium | H17: Canada | I17: 1 | J17: 0 | K17: 1 x 0 | L17: No | M17: Ahmad bin Ali Stadium | N17: Al Rayyan | O17: dato importado | P17: https://github.com/jfjelstul/worldcup
A18: M-2022-13 | B18: 2022 | C18: group | D18: Group G | E18: 1 | F18: 11/24/2022 | G18: SWITZERLAND | H18: Cameroon | I18: N/A | J18: 0 | K18: 1—0 | L18: 0 | M18: Al Janoub Stadium | N18: Al Wakrah | O18: ok | P18: https://github.com/jfjelstul/worldcup
A19: M-2022-14 | B19: 2022 | C19: Group Stage | D19: H | E19: 1 | F19: 24-11-22 | G19: Uruguay | H19: Korea Republic | I19: 0 | J19: 0 | K19: 0-0 | L19: FALSE | M19: Education City Stadium | N19: Al Rayyan | P19: https://github.com/jfjelstul/worldcup
A20: M-2022-15 | B20: 2022 | C20: Fase grupos | D20: Grupo H | E20: 1 | F20: Nov 24, 2022 | G20: Portugal | H20: Ghana | I20: 3 | J20: 2 | K20: 3–2 | L20: no | M20: Stadium 974 | N20: Doha | O20: revisar | P20: https://github.com/jfjelstul/worldcup
A21: M-2022-16 | B21: 2022 | C21: group | D21: G | E21: 1 | F21: 2022-11-24 | G21: Brasil | H21: serbia | I21: 2 | J21: 0 | K21: 2 : 0 | L21: No | M21: Lusail Stadium | N21: Lusail | O21: dato importado | P21: https://github.com/jfjelstul/worldcup
A22: M-2022-17 | B22: 2022 | C22: Group Stage | D22: Group B | E22: 2 | F22: 25/11/2022 | G22: Wales | H22: IR Iran | I22: 0 | J22: 2 | K22: 0 x 2 | L22: 0 | M22: Ahmad bin Ali Stadium | N22: Al Rayyan | O22: ok | P22: https://github.com/jfjelstul/worldcup
A23: M-2022-18 | B23: 2022 | C23: Fase grupos | D23: A | E23: 2 | F23: 11/25/2022 | G23: Qatar | H23: Senegal | I23: 1 | J23: 3 | K23: 1—3 | L23: TRUE | M23: Al Thumama Stadium | N23: Doha | P23: https://github.com/jfjelstul/worldcup
A24: M-2022-19 | B24: 2022 | C24: group | D24: Grupo A | E24: 2 | F24: 25-11-22 | G24: the netherlands | H24: Ecuador | I24: 1 | J24: 1 | K24: 1-1 | L24: no | M24: Khalifa International Stadium | N24: Al Rayyan | O24: revisar | P24: https://github.com/jfjelstul/worldcup
A25: M-2022-20 | B25: 2022 | C25: Group Stage | D25: B | E25: 2 | F25: Nov 25, 2022 | G25: England | H25: USA | I25: 0 | J25: 0 | K25: 0–0 | L25: No | M25: Al Bayt Stadium | N25: Al Khor | O25: dato importado | P25: https://github.com/jfjelstul/worldcup
A26: M-2022-21 | B26: 2022 | C26: Fase grupos | D26: Group D | E26: 2 | F26: 2022-11-26 | G26: Tunisia | H26: Australia | I26: 0 | J26: 1 | K26: 0 : 1 | L26: 0 | M26: Al Janoub Stadium | N26: Al Wakrah | O26: ok | P26: https://github.com/jfjelstul/worldcup
A27: M-2022-22 | B27: 2022 | C27: group | D27: C | E27: 2 | F27: 26/11/2022 | G27: Poland | H27: Saudi-Arabia | I27: 2 | J27: 0 | K27: 2 x 0 | L27: FALSE | M27: Education City Stadium | N27: Al Rayyan | P27: https://github.com/jfjelstul/worldcup
A28: M-2022-23 | B28: 2022 | C28: Group Stage | D28: Grupo D | E28: 2 | F28: 11/26/2022 | G28: France | H28: Denmark | I28: 2 | J28: 1 | K28: 2—1 | L28: no | M28: Stadium 974 | N28: Doha | O28: revisar | P28: https://github.com/jfjelstul/worldcup
A29: M-2022-24 | B29: 2022 | C29: Fase grupos | D29: C | E29: 2 | F29: 26-11-22 | G29: Argentina | H29: México | I29: 2 | J29: 0 | K29: 2-0 | L29: No | M29: Lusail Stadium | N29: Lusail | O29: dato importado | P29: https://github.com/jfjelstul/worldcup
A30: M-2022-25 | B30: 2022 | C30: group | D30: Group E | E30: 2 | F30: Nov 27, 2022 | G30: Japan | H30: Costa Rica | I30: N/A | J30: 1 | K30: 0–1 | L30: 0 | M30: Ahmad bin Ali Stadium | N30: Al Rayyan | O30: ok | P30: https://github.com/jfjelstul/worldcup
A31: M-2022-26 | B31: 2022 | C31: Group Stage | D31: F | E31: 2 | F31: 2022-11-27 | G31: Belgium | H31: Morocco | I31: 0 | J31: 2 | K31: 0 : 2 | L31: FALSE | M31: Al Thumama Stadium | N31: Doha | P31: https://github.com/jfjelstul/worldcup
A32: M-2022-27 | B32: 2022 | C32: Fase grupos | D32: Grupo F | E32: 2 | F32: 27/11/2022 | G32: Croatia | H32: CANADA | I32: 4 | J32: 1 | K32: 4 x 1 | L32: no | M32: Khalifa International Stadium | N32: Al Rayyan | O32: revisar | P32: https://github.com/jfjelstul/worldcup
A33: M-2022-28 | B33: 2022 | C33: group | D33: E | E33: 2 | F33: 11/27/2022 | G33: España | H33: Germany | I33: 1 | J33: -2 | K33: 1—1 | L33: No | M33: Al Bayt Stadium | N33: Al Khor | O33: dato importado | P33: https://github.com/jfjelstul/worldcup
A34: M-2022-29 | B34: 2022 | C34: Group Stage | D34: Group G | E34: 2 | F34: 28-11-22 | G34: Cameroon | H34: Serbia | I34: 3 | J34: 3 | K34: 3-3 | L34: 0 | M34: Al Janoub Stadium | N34: Al Wakrah | O34: ok | P34: https://github.com/jfjelstul/worldcup
A35: M-2022-30 | B35: 2022 | C35: Fase grupos | D35: H | E35: 2 | F35: Nov 28, 2022 | G35: REP. OF KOREA | H35: Ghana | I35: 2 | J35: 3 | K35: 2–3 | L35: FALSE | M35: Education City Stadium | N35: Al Rayyan | P35: https://github.com/jfjelstul/worldcup
A36: M-2022-31 | B36: 2022 | C36: group | D36: Grupo G | E36: 2 | G36: Brazil | H36: Suisse | I36: 1 | J36: 0 | K36: 1 : 0 | L36: no | M36: Stadium 974 | N36: Doha | O36: revisar | P36: https://github.com/jfjelstul/worldcup
A37: M-2022-32 | B37: 2022 | C37: Group Stage | D37: H | E37: 2 | F37: 28/11/2022 | G37: Portugal | H37: Uruguay | I37: 2 | J37: 0 | K37: 2 x 0 | L37: No | M37: Lusail Stadium | N37: Lusail | O37: dato importado | P37: https://github.com/jfjelstul/worldcup
A38: M-2022-33 | B38: 2022 | C38: Fase grupos | D38: Group A | E38: 3 | F38: 11/29/2022 | G38: Ecuador | H38: Senegal | I38: 1 | J38: 2 | K38: 1—2 | L38: 0 | M38: Khalifa International Stadium | N38: Al Rayyan | O38: ok | P38: https://github.com/jfjelstul/worldcup
A39: M-2022-34 | B39: 2022 | C39: group | D39: A | E39: 3 | F39: 29-11-22 | G39: The Netherlands | H39: Qatar | I39: 2 | J39: 0 | K39: 2-0 | L39: FALSE | M39: Al Bayt Stadium | N39: Al Khor | P39: https://github.com/jfjelstul/worldcup
A40: M-2022-35 | B40: 2022 | C40: Group Stage | D40: Grupo B | E40: 3 | F40: Nov 29, 2022 | G40: IR Iran | H40: USA | I40: 0 | J40: 1 | K40: 0–1 | L40: no | M40: Al Thumama Stadium | N40: Doha | O40: revisar | P40: https://github.com/jfjelstul/worldcup
A41: M-2022-36 | B41: 2022 | C41: Fase grupos | D41: B | E41: 3 | F41: 2022-11-29 | G41: Wales | H41: England | I41: 0 | J41: 3 | K41: 0 : 3 | L41: No | M41: Ahmad bin Ali Stadium | N41: Al Rayyan | O41: dato importado | P41: https://github.com/jfjelstul/worldcup
A42: M-2022-37 | B42: 2022 | C42: group | D42: Group D | E42: 3 | F42: 30/11/2022 | G42: Australia | H42: Denmark | I42: N/A | J42: 0 | K42: 1 x 0 | L42: 0 | M42: Al Janoub Stadium | N42: Al Wakrah | O42: ok | P42: https://github.com/jfjelstul/worldcup
...

Sheet 05_Sucio_2026
A1: 05 Sucio 2026
A2: Incluye 12 grupos y una fecha almacenada como número serial de Excel.
A5: match | B5: wc | C5: round | D5: grp | E5: md | F5: played_on | G5: home | H5: away | I5: HG | J5: AG | K5: result_raw | L5: host_h | M5: host_a | N5: source
A6: M-2026-001 | B6: 2026 | C6: GS | D6: A | E6: 1 | F6: 2026-06-11 | G6: México | H6: South Africa | J6: s/d | K6: 2–0 | L6: TRUE | M6: no | N6: https://en.wikipedia.org/wiki/2026_FIFA_World_Cup_Group_A
A7: M-2026-002 | B7: 2026 | C7: group stage | D7: Grupo A | E7: 1 | F7: 12/06/2026 | G7: Korea Rep. | H7: Czech Republic | I7: 2 | J7: 1 | K7: 2 : 1 | L7: no | M7: No | N7: https://en.wikipedia.org/wiki/2026_FIFA_World_Cup_Group_A
A8: M-2026-007 | B8: 2026 | C8: fase de grupos | D8: group-b | E8: 1 | F8: 06/12/2026 | G8: Canada | H8: BOSNIA & HERZEGOVINA | I8: 1 | J8: 1 | K8: 1 x 1 | L8: Sí | M8: 0 | N8: https://en.wikipedia.org/wiki/2026_FIFA_World_Cup_Group_B
A9: M-2026-008 | B9: 2026 | C9: GS | D9: B | E9: 1 | F9: 13-06-26 | G9: Qatar | H9: Suisse | I9: 1 | J9: 1 | K9: 1—1 | L9: 0 | M9: FALSE | N9: https://en.wikipedia.org/wiki/2026_FIFA_World_Cup_Group_B
A10: M-2026-013 | B10: 2026 | C10: group stage | D10: C | E10: 1 | F10: Jun 13, 2026 | G10: Brazil | H10: Morocco | I10: 1 | J10: 1 | K10: 1-1 | L10: FALSE | M10: no | N10: https://en.wikipedia.org/wiki/2026_FIFA_World_Cup_Group_C
A11: M-2026-014 | B11: 2026 | C11: fase de grupos | D11: Grupo C | E11: 1 | F11: 2026-06-13 | G11: Haiti | H11: Scotland | I11: 0 | J11: 1 | K11: 0–1 | L11: no | M11: No | N11: https://en.wikipedia.org/wiki/2026_FIFA_World_Cup_Group_C
A12: M-2026-019 | B12: 2026 | C12: GS | D12: group-d | E12: 1 | F12: 13/06/2026 | G12: USA | H12: Paraguay | I12: 4 | J12: 1 | K12: 4 : 1 | L12: Sí | M12: 0 | N12: https://en.wikipedia.org/wiki/2026_FIFA_World_Cup_Group_D
A13: M-2026-020 | B13: 2026 | C13: group stage | D13: D | E13: 1 | F13: 46187 | G13: Australia | H13: Turkiye | I13: 2 | J13: 0 | K13: 2 x 0 | L13: 0 | M13: FALSE | N13: https://en.wikipedia.org/wiki/2026_FIFA_World_Cup_Group_D
A14: M-2026-025 | B14: 2026 | C14: fase de grupos | D14: E | E14: 1 | F14: 14-06-26 | G14: Germany | H14: curaçao | I14: 7 | J14: 1 | K14: 7—1 | L14: FALSE | M14: no | N14: https://en.wikipedia.org/wiki/2026_FIFA_World_Cup_Group_E
A15: M-2026-026 | B15: 2026 | C15: GS | D15: Grupo E | E15: 1 | F15: Jun 14, 2026 | G15: Cote d Ivoire | H15: Ecuador | I15: 1 | J15: 0 | K15: 1-0 | L15: no | M15: No | N15: https://en.wikipedia.org/wiki/2026_FIFA_World_Cup_Group_E
A16: M-2026-031 | B16: 2026 | C16: group stage | D16: group-f | E16: 1 | F16: 2026-06-14 | G16: Holland | H16: Japan | J16: 2 | K16: 2–2 | L16: No | M16: 0 | N16: https://en.wikipedia.org/wiki/2026_FIFA_World_Cup_Group_F
A17: M-2026-032 | B17: 2026 | C17: fase de grupos | D17: F | E17: 1 | F17: 15/06/2026 | G17: Sweden | H17: Tunisia | I17: 5 | J17: 1 | K17: 5 : 1 | L17: 0 | M17: FALSE | N17: https://en.wikipedia.org/wiki/2026_FIFA_World_Cup_Group_F
A18: M-2026-037 | B18: 2026 | C18: GS | E18: 1 | F18: 06/15/2026 | G18: belgium | H18: Egypt | I18: 1 | J18: 1 | K18: 1 x 1 | L18: FALSE | M18: no | N18: https://en.wikipedia.org/wiki/2026_FIFA_World_Cup_Group_G
A19: M-2026-038 | B19: 2026 | C19: group stage | D19: Grupo G | E19: 1 | F19: 15-06-26 | G19: IR Iran | H19: New Zealand | I19: 2 | J19: 2 | K19: 2—2 | L19: no | M19: No | N19: https://en.wikipedia.org/wiki/2026_FIFA_World_Cup_Group_G
A20: M-2026-043 | B20: 2026 | C20: fase de grupos | D20: group-h | E20: 1 | F20: Jun 15, 2026 | G20: Spain | H20: Cape-Verde | I20: 0 | J20: s/d | K20: 0-0 | L20: No | M20: 0 | N20: https://en.wikipedia.org/wiki/2026_FIFA_World_Cup_Group_H
A21: M-2026-044 | B21: 2026 | C21: GS | D21: H | E21: 1 | F21: 2026-06-15 | G21: Saudi-Arabia | H21: Uruguay | I21: 1 | J21: 1 | K21: 1–1 | L21: 0 | M21: FALSE | N21: https://en.wikipedia.org/wiki/2026_FIFA_World_Cup_Group_H
A22: M-2026-049 | B22: 2026 | C22: group stage | D22: I | E22: 1 | F22: 16/06/2026 | G22: France | H22: Senegal | I22: 3 | J22: 1 | K22: 3 : 1 | L22: FALSE | M22: no | N22: https://en.wikipedia.org/wiki/2026_FIFA_World_Cup_Group_I
A23: M-2026-050 | B23: 2026 | C23: fase de grupos | D23: Grupo I | E23: 1 | F23: 06/16/2026 | G23: Iraq | H23: Norway | I23: 1 | J23: 4 | K23: 1 x 4 | L23: no | M23: No | N23: https://en.wikipedia.org/wiki/2026_FIFA_World_Cup_Group_I
A24: M-2026-055 | B24: 2026 | C24: GS | D24: group-j | E24: 1 | F24: 16-06-26 | G24: Argentina | H24: Algeria | I24: 3 | J24: 0 | K24: 3—0 | L24: No | M24: 0 | N24: https://en.wikipedia.org/wiki/2026_FIFA_World_Cup_Group_J
A25: M-2026-056 | B25: 2026 | C25: group stage | D25: J | E25: 1 | F25: Jun 17, 2026 | G25: Austria | H25: JORDAN | I25: 3 | J25: 1 | K25: 3-1 | L25: 0 | M25: FALSE | N25: https://en.wikipedia.org/wiki/2026_FIFA_World_Cup_Group_J
A26: M-2026-061 | B26: 2026 | C26: fase de grupos | D26: K | E26: 1 | F26: 2026-06-17 | G26: Portugal | H26: Democratic Republic of the Congo | J26: 1 | K26: 1–1 | L26: FALSE | M26: no | N26: https://en.wikipedia.org/wiki/2026_FIFA_World_Cup_Group_K
A27: M-2026-062 | B27: 2026 | C27: GS | D27: Grupo K | E27: 1 | F27: 17/06/2026 | G27: Uzbekistan | H27: Colombia | I27: 1 | J27: 3 | L27: no | M27: No | N27: https://en.wikipedia.org/wiki/2026_FIFA_World_Cup_Group_K
A28: M-2026-067 | B28: 2026 | C28: group stage | D28: group-l | E28: 1 | F28: 06/17/2026 | G28: England | H28: Croatia | I28: 4 | J28: 2 | K28: 4 x 2 | L28: No | M28: 0 | N28: https://en.wikipedia.org/wiki/2026_FIFA_World_Cup_Group_L
A29: M-2026-003 | B29: 2026 | C29: fase de grupos | D29: A | E29: 2 | F29: 18-06-26 | G29: CZECH REPUBLIC | H29: South Africa | I29: 1 | J29: 1 | K29: 1—1 | L29: 0 | M29: FALSE | N29: https://en.wikipedia.org/wiki/2026_FIFA_World_Cup_Group_A
A30: M-2026-004 | B30: 2026 | C30: GS | D30: A | E30: 2 | F30: Jun 18, 2026 | G30: México | H30: South Korea | I30: 1 | J30: 0 | K30: 1-0 | L30: TRUE | M30: no | N30: https://en.wikipedia.org/wiki/2026_FIFA_World_Cup_Group_A
A31: M-2026-009 | B31: 2026 | C31: group stage | D31: Grupo B | E31: 2 | F31: 2026-06-18 | G31: Suisse | H31: Bosnia | I31: 4 | J31: 1 | K31: 4–1 | L31: no | M31: No | N31: https://en.wikipedia.org/wiki/2026_FIFA_World_Cup_Group_B
A32: M-2026-010 | B32: 2026 | C32: fase de grupos | D32: group-b | E32: 2 | F32: 18/06/2026 | G32: Canada | H32: Qatar | I32: 6 | J32: 0 | K32: 6 : 0 | L32: Sí | M32: 0 | N32: https://en.wikipedia.org/wiki/2026_FIFA_World_Cup_Group_B
A33: M-2026-068 | B33: 2026 | C33: GS | D33: L | E33: 1 | F33: 06/18/2026 | G33: Ghana | H33: Panama | I33: 1 | J33: 0 | K33: 1 x 0 | L33: 0 | M33: FALSE | N33: https://en.wikipedia.org/wiki/2026_FIFA_World_Cup_Group_L
A34: M-2026-015 | B34: 2026 | C34: group stage | D34: C | E34: 2 | F34: 19-06-26 | G34: Scotland | H34: Morocco | I34: 0 | J34: s/d | K34: 0—1 | L34: FALSE | M34: no | N34: https://en.wikipedia.org/wiki/2026_FIFA_World_Cup_Group_C
A35: M-2026-016 | B35: 2026 | C35: fase de grupos | D35: Grupo C | E35: 2 | F35: Jun 19, 2026 | G35: Brasil | H35: Haiti | I35: 3 | J35: 0 | K35: 3-0 | L35: no | M35: No | N35: https://en.wikipedia.org/wiki/2026_FIFA_World_Cup_Group_C
A36: M-2026-021 | B36: 2026 | C36: GS | D36: group-d | E36: 2 | F36: 2026-06-19 | G36: US | H36: Australia | J36: 0 | K36: 2–0 | L36: Sí | M36: 0 | N36: https://en.wikipedia.org/wiki/2026_FIFA_World_Cup_Group_D
A37: M-2026-022 | B37: 2026 | C37: group stage | D37: D | E37: 2 | F37: 20/06/2026 | G37: Turkey | H37: paraguay | I37: 0 | J37: 1 | K37: 0 : 1 | L37: 0 | M37: FALSE | N37: https://en.wikipedia.org/wiki/2026_FIFA_World_Cup_Group_D
A38: M-2026-027 | B38: 2026 | C38: fase de grupos | D38: E | E38: 2 | F38: 06/20/2026 | G38: Germany | H38: Ivory Coast | I38: 2 | J38: 1 | K38: 2 x 1 | L38: FALSE | M38: no | N38: https://en.wikipedia.org/wiki/2026_FIFA_World_Cup_Group_E
A39: M-2026-028 | B39: 2026 | C39: GS | D39: Grupo E | E39: 2 | F39: 20-06-26 | G39: Ecuador | H39: CURACAO | I39: 0 | J39: 0 | K39: 0—0 | L39: no | M39: No | N39: https://en.wikipedia.org/wiki/2026_FIFA_World_Cup_Group_E
A40: M-2026-033 | B40: 2026 | C40: group stage | D40: group-f | E40: 2 | F40: Jun 20, 2026 | G40: Holland | H40: Sweden | I40: 5 | J40: 1 | K40: 5-1 | L40: No | M40: 0 | N40: https://en.wikipedia.org/wiki/2026_FIFA_World_Cup_Group_F
A41: M-2026-034 | B41: 2026 | C41: fase de grupos | D41: F | E41: 2 | F41: 2026-06-20 | G41: tunisia | H41: Japan | I41: 0 | J41: 4 | K41: 0–4 | L41: 0 | M41: FALSE | N41: https://en.wikipedia.org/wiki/2026_FIFA_World_Cup_Group_F
A42: M-2026-039 | B42: 2026 | C42: GS | D42: G | E42: 2 | F42: 21/06/2026 | G42: Belgium | H42: IR IRAN | I42: 0 | J42: 0 | K42: 0 : 0 | L42: FALSE | M42: no | N42: https://en.wikipedia.org/wiki/2026_FIFA_World_Cup_Group_G
...

Sheet 06_Control_Calidad
A1: Bitácora y control de calidad
A2: Completa las columnas amarillas durante el laboratorio. Una corrección sin evidencia no está terminada.
A5: Dimensión | B5: Problema | C5: Cómo detectarlo | D5: Criterio de aceptación | E5: Resultado | F5: Decisión aplicada | G5: Evidencia / fórmula
A6: Estructura | B6: Columnas equivalentes con nombres diferentes | C6: Comparar encabezados | D6: Esquema canónico definido | E6: Confirmado: 2018 (16 cols: ID Partido…Fuente), 2022 (16 cols: match_id…source_url), 2026 (14 cols: match…source). Ningún nombre de columna coincide entre los tres archivos. | F6: Mapear cada archivo al esquema canónico de 14 campos (hoja 01_Diccionario) con un diccionario de renombrado por año; no fusionar directo. | G6: Comparación manual de encabezados (fila 5 de cada hoja sucia) + diccionario de renombrado en Python.
A7: Completitud | B7: Valores vacíos en campos críticos | C7: Filtros / CONTAR.BLANCO | D7: 0 nulos en equipo, grupo y goles | E7: 2018: 1 nulo real en Grupo (M-2018-10) + 3 en Goles Visitante + 1 en Marcador, más 1 valor centinela "s/d" en Grupo (M-2018-32). 2022: 1 nulo en group_name, 1 en date, 4 en home_score. 2026: 1 nulo en grp, 9 en HG, 1 en result_raw. Equipo local/visitante: 0 nulos en los tres archivos. | F7: Rellenar goles faltantes con el marcador; grupo faltante se infiere del grupo más frecuente del mismo equipo en ese mundial; "s/d"/"N/D" se tratan como vacío, nunca como grupo D. | G7: Fórmula: CONTAR.BLANCO(rango) por columna en cada hoja sucia.
A8: Unicidad | B8: Partidos repetidos | C8: Formato condicional / CONTAR.SI | D8: 168 IDs únicos | E8: 2018: 50 filas con 2 IDs duplicados (M-2018-05, M-2018-18) → 48 únicos. 2022: 51 filas con 3 filas duplicadas (M-2022-03 x3, M-2022-42 x2) → 48 únicos. 2026: 75 filas con 3 IDs duplicados (M-2026-019, -051, -065) → 72 únicos. Total 176 filas crudas → 168 partidos únicos. | F8: Eliminar duplicados exactos por partido_id, conservando la primera aparición. | G8: Formato condicional "Valores duplicados" + =CONTAR.SI(A:A,A6). Verificado en 07_Base_Limpia: 0 partido_id repetidos.
A9: Validez | B9: Goles negativos o texto | C9: Filtros y conversión numérica | D9: Todos enteros >= 0 | E9: Texto en vez de número: 2018 Goles Local = "5 goles"/"1 goles" (M-2018-05, M-2018-18). 2026 AG = "s/d" en 3 partidos. Negativos: 2018 Goles Local=-1 (M-2018-23), 2022 away_score=-2 (M-2022-28), 2026 HG=-1 (M-2026-046). | F9: Extraer el primer entero con regex; cualquier negativo se descarta y se repara con el marcador. | G9: Filtro "no es número" + =ESNUMERO(celda). Verificado en 07_Base_Limpia: 0 goles negativos (ver 11_Pruebas_QA).
A10: Consistencia | B10: Marcador y goles separados no coinciden | C10: Comparar ambos campos | D10: 0 conflictos pendientes | E10: 3 conflictos, uno por archivo: M-2018-23 (goles -1/3; marcador "0:3"), M-2022-28 (goles 1/-2; marcador "1-1"), M-2026-046 (goles -1/2; marcador "2-2"). El marcador era el dato correcto en los 3 casos. | F10: Cuando el marcador se separa en dos números válidos, prevalece sobre los goles sueltos (regla 1 del paso 7 de la guía). | G10: Columna auxiliar comparando goles vs marcador. Resultado final en 07_Base_Limpia, fila K: marcador siempre coincide con goles_local-goles_visitante.
A11: Consistencia | B11: Fechas mezcladas o seriales | C11: Formato de celda y rango del torneo | D11: Todas son fechas válidas | E11: Formatos mezclados: ISO, DD/MM/AAAA, MM/DD/AAAA, DD-MM-AA, texto ("Jun 16, 2018"). 2026 trae 1 fecha como serial de Excel puro: "46187" en M-2026-020 (=12 jun 2026). Además, 2 partidos (M-2022-31, M-2026-024) no traen fecha en la fuente original (NaN y "N/D"): se dejaron en blanco, no se inventaron. | F11: Probar varios patrones de fecha; para el serial sumar días al origen 1899-12-30; validar contra el rango oficial del torneo. Los 2 casos sin fecha real quedan pendientes de revisión docente. | G11: Formato de celda + comparación contra rango 2018:14-28 jun / 2022:20 nov-2 dic / 2026:11-27 jun.
A12: Categorías | B12: Nombres de equipos con variantes | C12: Catálogo + BUSCARX | D12: Una forma canónica por equipo | E12: Se probaron todas las variantes de equipo contra catalogo_equipos.csv (acentos/mayúsculas normalizados): 0 casos sin equivalencia. El catálogo cubre el 100% de las variantes usadas. | F12: BUSCARX con clave normalizada (sin acentos, minúsculas, sin signos) contra la columna Variante; se conserva el acento en el nombre final mostrado. | G12: Fórmula: BUSCARX(clave;02_catalogo_equipos!clave;...!B:B;"SIN MATCH") → 0 filas con SIN MATCH. 32/32/48 equipos únicos por mundial (ver 11_Pruebas_QA).
A13: Categorías | B13: Grupos escritos de formas distintas | C13: Extraer letra A-L | D13: Solo A-L | E13: Formatos mezclados: "Grupo A", "group-a", "A ", mayúsc/minúsc. Riesgo detectado: una extracción ingenua de la primera letra A-L confundía la "G" de "Grupo" con el grupo real, y la "D" de "s/d" con el Grupo D. Se corrigió exigiendo la letra como palabra completa y excluyendo centinelas. | F13: Extraer solo una letra A-L que sea palabra completa (no parte de "Grupo"/"Group"); tratar "s/d"/"N/D" como vacío y resolver por inferencia desde el historial del equipo. | G13: Verificado en 07_Base_Limpia: cada grupo tiene exactamente 6 partidos (round robin de 4 equipos) en los 8 grupos de 2018/2022 y los 12 de 2026 (ver 11_Pruebas_QA).
A14: Comparabilidad | B14: 2026 tiene más partidos | C14: Calcular tasas | D14: Usar goles/partido y porcentajes | E14: Confirmado: 2018 y 2022 = 48 partidos (32 equipos); 2026 = 72 partidos (48 equipos), 50% más partidos. | F14: Usar tasas (goles/partido, % empates, % victoria anfitrión, % partidos >2.5 goles) en 08_Comparacion, nunca sumas totales solas. | G14: Hoja 08_Comparacion, columnas D/F/I/J, ya calculadas con fórmulas.
A15: Trazabilidad | B15: Cambios sin justificar | C15: Bitácora | D15: Cada regla tiene evidencia | E15: Cada corrección de esta bitácora queda documentada con el partido_id exacto afectado. | F15: Mantener esta tabla actualizada; cualquier cambio en las hojas sucias o en la base limpia debe poder rastrearse hasta una fila de aquí. | G15: Esta misma tabla + hoja 11_Pruebas_QA con las pruebas automatizadas de todo el proceso. Ejemplo real: se detectó que 08_Comparacion comparaba anfitrión contra el texto "Sí", pero 07_Base_Limpia usa booleano TRUE/FALSE (como pide 01_Diccionario); se corrigió la fórmula para comparar contra TRUE.

Sheet 07_Base_Limpia
A1: Base integrada limpia
A2: Pega únicamente los campos de entrada. Las columnas azules se calculan con fórmulas.
A5: partido_id | B5: mundial | C5: fase | D5: grupo | E5: jornada | F5: fecha | G5: equipo_local | H5: equipo_visitante | I5: goles_local | J5: goles_visitante | K5: marcador | L5: resultado_local | M5: local_es_anfitrion | N5: visitante_es_anfitrion | O5: goles_totales | P5: diferencia_goles | Q5: puntos_local | R5: puntos_visitante | S5: fuente
A6: M-2018-01 | B6: 2018 | C6: Fase de grupos | D6: A | E6: 1 | F6: 43265 | G6: Russia | H6: Saudi Arabia | I6: 5 | J6: 0 | K6: =IF(OR(I6="",J6=""),"",I6&"-"&J6) -> 5-0 | L6: =IF(OR(I6="",J6=""),"",IF(I6>J6,"Gana",IF(I6=J6,"Empata","Pierde"))) -> Gana | M6: =TRUE() -> TRUE | N6: =FALSE() -> FALSE | O6: =IF(OR(I6="",J6=""),"",I6+J6) -> 5 | P6: =IF(OR(I6="",J6=""),"",I6-J6) -> 5 | Q6: =IF(L6="","",IF(L6="Gana",3,IF(L6="Empata",1,0))) -> 3 | R6: =IF(L6="","",IF(L6="Pierde",3,IF(L6="Empata",1,0))) -> 0 | S6: https://github.com/jfjelstul/worldcup
A7: M-2018-02 | B7: 2018 | C7: Fase de grupos | D7: A | E7: 1 | F7: 43266 | G7: Egypt | H7: Uruguay | I7: 0 | J7: 1 | K7: =IF(OR(I7="",J7=""),"",I7&"-"&J7) -> 0-1 | L7: =IF(OR(I7="",J7=""),"",IF(I7>J7,"Gana",IF(I7=J7,"Empata","Pierde"))) -> Pierde | M7: =FALSE() -> FALSE | N7: =FALSE() -> FALSE | O7: =IF(OR(I7="",J7=""),"",I7+J7) -> 1 | P7: =IF(OR(I7="",J7=""),"",I7-J7) -> -1 | Q7: =IF(L7="","",IF(L7="Gana",3,IF(L7="Empata",1,0))) -> 0 | R7: =IF(L7="","",IF(L7="Pierde",3,IF(L7="Empata",1,0))) -> 3 | S7: https://github.com/jfjelstul/worldcup
A8: M-2018-03 | B8: 2018 | C8: Fase de grupos | D8: B | E8: 1 | F8: 43266 | G8: Morocco | H8: Iran | I8: 0 | J8: 1 | K8: =IF(OR(I8="",J8=""),"",I8&"-"&J8) -> 0-1 | L8: =IF(OR(I8="",J8=""),"",IF(I8>J8,"Gana",IF(I8=J8,"Empata","Pierde"))) -> Pierde | M8: =FALSE() -> FALSE | N8: =FALSE() -> FALSE | O8: =IF(OR(I8="",J8=""),"",I8+J8) -> 1 | P8: =IF(OR(I8="",J8=""),"",I8-J8) -> -1 | Q8: =IF(L8="","",IF(L8="Gana",3,IF(L8="Empata",1,0))) -> 0 | R8: =IF(L8="","",IF(L8="Pierde",3,IF(L8="Empata",1,0))) -> 3 | S8: https://github.com/jfjelstul/worldcup
A9: M-2018-04 | B9: 2018 | C9: Fase de grupos | D9: B | E9: 1 | F9: 43266 | G9: Portugal | H9: Spain | I9: 3 | J9: 3 | K9: =IF(OR(I9="",J9=""),"",I9&"-"&J9) -> 3-3 | L9: =IF(OR(I9="",J9=""),"",IF(I9>J9,"Gana",IF(I9=J9,"Empata","Pierde"))) -> Empata | M9: =FALSE() -> FALSE | N9: =FALSE() -> FALSE | O9: =IF(OR(I9="",J9=""),"",I9+J9) -> 6 | P9: =IF(OR(I9="",J9=""),"",I9-J9) -> 0 | Q9: =IF(L9="","",IF(L9="Gana",3,IF(L9="Empata",1,0))) -> 1 | R9: =IF(L9="","",IF(L9="Pierde",3,IF(L9="Empata",1,0))) -> 1 | S9: https://github.com/jfjelstul/worldcup
A10: M-2018-05 | B10: 2018 | C10: Fase de grupos | D10: C | E10: 1 | F10: 43267 | G10: France | H10: Australia | I10: 2 | J10: 1 | K10: =IF(OR(I10="",J10=""),"",I10&"-"&J10) -> 2-1 | L10: =IF(OR(I10="",J10=""),"",IF(I10>J10,"Gana",IF(I10=J10,"Empata","Pierde"))) -> Gana | M10: =FALSE() -> FALSE | N10: =FALSE() -> FALSE | O10: =IF(OR(I10="",J10=""),"",I10+J10) -> 3 | P10: =IF(OR(I10="",J10=""),"",I10-J10) -> 1 | Q10: =IF(L10="","",IF(L10="Gana",3,IF(L10="Empata",1,0))) -> 3 | R10: =IF(L10="","",IF(L10="Pierde",3,IF(L10="Empata",1,0))) -> 0 | S10: https://github.com/jfjelstul/worldcup
A11: M-2018-06 | B11: 2018 | C11: Fase de grupos | D11: D | E11: 1 | F11: 43267 | G11: Argentina | H11: Iceland | I11: 1 | J11: 1 | K11: =IF(OR(I11="",J11=""),"",I11&"-"&J11) -> 1-1 | L11: =IF(OR(I11="",J11=""),"",IF(I11>J11,"Gana",IF(I11=J11,"Empata","Pierde"))) -> Empata | M11: =FALSE() -> FALSE | N11: =FALSE() -> FALSE | O11: =IF(OR(I11="",J11=""),"",I11+J11) -> 2 | P11: =IF(OR(I11="",J11=""),"",I11-J11) -> 0 | Q11: =IF(L11="","",IF(L11="Gana",3,IF(L11="Empata",1,0))) -> 1 | R11: =IF(L11="","",IF(L11="Pierde",3,IF(L11="Empata",1,0))) -> 1 | S11: https://github.com/jfjelstul/worldcup
A12: M-2018-07 | B12: 2018 | C12: Fase de grupos | D12: C | E12: 1 | F12: 43267 | G12: Peru | H12: Denmark | I12: 0 | J12: 1 | K12: =IF(OR(I12="",J12=""),"",I12&"-"&J12) -> 0-1 | L12: =IF(OR(I12="",J12=""),"",IF(I12>J12,"Gana",IF(I12=J12,"Empata","Pierde"))) -> Pierde | M12: =FALSE() -> FALSE | N12: =FALSE() -> FALSE | O12: =IF(OR(I12="",J12=""),"",I12+J12) -> 1 | P12: =IF(OR(I12="",J12=""),"",I12-J12) -> -1 | Q12: =IF(L12="","",IF(L12="Gana",3,IF(L12="Empata",1,0))) -> 0 | R12: =IF(L12="","",IF(L12="Pierde",3,IF(L12="Empata",1,0))) -> 3 | S12: https://github.com/jfjelstul/worldcup
A13: M-2018-08 | B13: 2018 | C13: Fase de grupos | D13: D | E13: 1 | F13: 43267 | G13: Croatia | H13: Nigeria | I13: 2 | J13: 0 | K13: =IF(OR(I13="",J13=""),"",I13&"-"&J13) -> 2-0 | L13: =IF(OR(I13="",J13=""),"",IF(I13>J13,"Gana",IF(I13=J13,"Empata","Pierde"))) -> Gana | M13: =FALSE() -> FALSE | N13: =FALSE() -> FALSE | O13: =IF(OR(I13="",J13=""),"",I13+J13) -> 2 | P13: =IF(OR(I13="",J13=""),"",I13-J13) -> 2 | Q13: =IF(L13="","",IF(L13="Gana",3,IF(L13="Empata",1,0))) -> 3 | R13: =IF(L13="","",IF(L13="Pierde",3,IF(L13="Empata",1,0))) -> 0 | S13: https://github.com/jfjelstul/worldcup
A14: M-2018-09 | B14: 2018 | C14: Fase de grupos | D14: E | E14: 1 | F14: 43268 | G14: Costa Rica | H14: Serbia | I14: 0 | J14: 1 | K14: =IF(OR(I14="",J14=""),"",I14&"-"&J14) -> 0-1 | L14: =IF(OR(I14="",J14=""),"",IF(I14>J14,"Gana",IF(I14=J14,"Empata","Pierde"))) -> Pierde | M14: =FALSE() -> FALSE | N14: =FALSE() -> FALSE | O14: =IF(OR(I14="",J14=""),"",I14+J14) -> 1 | P14: =IF(OR(I14="",J14=""),"",I14-J14) -> -1 | Q14: =IF(L14="","",IF(L14="Gana",3,IF(L14="Empata",1,0))) -> 0 | R14: =IF(L14="","",IF(L14="Pierde",3,IF(L14="Empata",1,0))) -> 3 | S14: https://github.com/jfjelstul/worldcup
A15: M-2018-10 | B15: 2018 | C15: Fase de grupos | D15: F | E15: 1 | F15: 43268 | G15: Germany | H15: Mexico | I15: 0 | J15: 1 | K15: =IF(OR(I15="",J15=""),"",I15&"-"&J15) -> 0-1 | L15: =IF(OR(I15="",J15=""),"",IF(I15>J15,"Gana",IF(I15=J15,"Empata","Pierde"))) -> Pierde | M15: =FALSE() -> FALSE | N15: =FALSE() -> FALSE | O15: =IF(OR(I15="",J15=""),"",I15+J15) -> 1 | P15: =IF(OR(I15="",J15=""),"",I15-J15) -> -1 | Q15: =IF(L15="","",IF(L15="Gana",3,IF(L15="Empata",1,0))) -> 0 | R15: =IF(L15="","",IF(L15="Pierde",3,IF(L15="Empata",1,0))) -> 3 | S15: https://github.com/jfjelstul/worldcup
A16: M-2018-11 | B16: 2018 | C16: Fase de grupos | D16: E | E16: 1 | F16: 43268 | G16: Brazil | H16: Switzerland | I16: 1 | J16: 1 | K16: =IF(OR(I16="",J16=""),"",I16&"-"&J16) -> 1-1 | L16: =IF(OR(I16="",J16=""),"",IF(I16>J16,"Gana",IF(I16=J16,"Empata","Pierde"))) -> Empata | M16: =FALSE() -> FALSE | N16: =FALSE() -> FALSE | O16: =IF(OR(I16="",J16=""),"",I16+J16) -> 2 | P16: =IF(OR(I16="",J16=""),"",I16-J16) -> 0 | Q16: =IF(L16="","",IF(L16="Gana",3,IF(L16="Empata",1,0))) -> 1 | R16: =IF(L16="","",IF(L16="Pierde",3,IF(L16="Empata",1,0))) -> 1 | S16: https://github.com/jfjelstul/worldcup
A17: M-2018-12 | B17: 2018 | C17: Fase de grupos | D17: F | E17: 1 | F17: 43269 | G17: Sweden | H17: South Korea | I17: 1 | J17: 0 | K17: =IF(OR(I17="",J17=""),"",I17&"-"&J17) -> 1-0 | L17: =IF(OR(I17="",J17=""),"",IF(I17>J17,"Gana",IF(I17=J17,"Empata","Pierde"))) -> Gana | M17: =FALSE() -> FALSE | N17: =FALSE() -> FALSE | O17: =IF(OR(I17="",J17=""),"",I17+J17) -> 1 | P17: =IF(OR(I17="",J17=""),"",I17-J17) -> 1 | Q17: =IF(L17="","",IF(L17="Gana",3,IF(L17="Empata",1,0))) -> 3 | R17: =IF(L17="","",IF(L17="Pierde",3,IF(L17="Empata",1,0))) -> 0 | S17: https://github.com/jfjelstul/worldcup
A18: M-2018-13 | B18: 2018 | C18: Fase de grupos | D18: G | E18: 1 | F18: 43269 | G18: Belgium | H18: Panama | I18: 3 | J18: 0 | K18: =IF(OR(I18="",J18=""),"",I18&"-"&J18) -> 3-0 | L18: =IF(OR(I18="",J18=""),"",IF(I18>J18,"Gana",IF(I18=J18,"Empata","Pierde"))) -> Gana | M18: =FALSE() -> FALSE | N18: =FALSE() -> FALSE | O18: =IF(OR(I18="",J18=""),"",I18+J18) -> 3 | P18: =IF(OR(I18="",J18=""),"",I18-J18) -> 3 | Q18: =IF(L18="","",IF(L18="Gana",3,IF(L18="Empata",1,0))) -> 3 | R18: =IF(L18="","",IF(L18="Pierde",3,IF(L18="Empata",1,0))) -> 0 | S18: https://github.com/jfjelstul/worldcup
... A21: M-2018-16 | B21: 2018 | C21: Fase de grupos | D21: H | E21: 1 | F21: 43270 | G21: Poland | H21: Senegal | I21: 1 | J21: 2 | K21: =IF(OR(I21="",J21=""),"",I21&"-"&J21) -> 1-2 | L21: =IF(OR(I21="",J21=""),"",IF(I21>J21,"Gana",IF(I21=J21,"Empata","Pierde"))) -> Pierde | M21: =FALSE() -> FALSE | N21: =FALSE() -> FALSE | O21: =IF(OR(I21="",J21=""),"",I21+J21) -> 3 | P21: =IF(OR(I21="",J21=""),"",I21-J21) -> -1 | Q21: =IF(L21="","",IF(L21="Gana",3,IF(L21="Empata",1,0))) -> 0 | R21: =IF(L21="","",IF(L21="Pierde",3,IF(L21="Empata",1,0))) -> 3 | S21: https://github.com/jfjelstul/worldcup
A22: M-2018-17 | B22: 2018 | C22: Fase de grupos | D22: A | E22: 2 | F22: 43270 | G22: Russia | H22: Egypt | I22: 3 | J22: 1 | K22: =IF(OR(I22="",J22=""),"",I22&"-"&J22) -> 3-1 | L22: =IF(OR(I22="",J22=""),"",IF(I22>J22,"Gana",IF(I22=J22,"Empata","Pierde"))) -> Gana | M22: =TRUE() -> TRUE | N22: =FALSE() -> FALSE | O22: =IF(OR(I22="",J22=""),"",I22+J22) -> 4 | P22: =IF(OR(I22="",J22=""),"",I22-J22) -> 2 | Q22: =IF(L22="","",IF(L22="Gana",3,IF(L22="Empata",1,0))) -> 3 | R22: =IF(L22="","",IF(L22="Pierde",3,IF(L22="Empata",1,0))) -> 0 | S22: https://github.com/jfjelstul/worldcup
A23: M-2018-18 | B23: 2018 | C23: Fase de grupos | D23: B | E23: 2 | F23: 43271 | G23: Portugal | H23: Morocco | I23: 1 | J23: 0 | K23: =IF(OR(I23="",J23=""),"",I23&"-"&J23) -> 1-0 | L23: =IF(OR(I23="",J23=""),"",IF(I23>J23,"Gana",IF(I23=J23,"Empata","Pierde"))) -> Gana | M23: =FALSE() -> FALSE | N23: =FALSE() -> FALSE | O23: =IF(OR(I23="",J23=""),"",I23+J23) -> 1 | P23: =IF(OR(I23="",J23=""),"",I23-J23) -> 1 | Q23: =IF(L23="","",IF(L23="Gana",3,IF(L23="Empata",1,0))) -> 3 | R23: =IF(L23="","",IF(L23="Pierde",3,IF(L23="Empata",1,0))) -> 0 | S23: https://github.com/jfjelstul/worldcup
A24: M-2018-19 | B24: 2018 | C24: Fase de grupos | D24: A | E24: 2 | F24: 43271 | G24: Uruguay | H24: Saudi Arabia | I24: 1 | J24: 0 | K24: =IF(OR(I24="",J24=""),"",I24&"-"&J24) -> 1-0 | L24: =IF(OR(I24="",J24=""),"",IF(I24>J24,"Gana",IF(I24=J24,"Empata","Pierde"))) -> Gana | M24: =FALSE() -> FALSE | N24: =FALSE() -> FALSE | O24: =IF(OR(I24="",J24=""),"",I24+J24) -> 1 | P24: =IF(OR(I24="",J24=""),"",I24-J24) -> 1 | Q24: =IF(L24="","",IF(L24="Gana",3,IF(L24="Empata",1,0))) -> 3 | R24: =IF(L24="","",IF(L24="Pierde",3,IF(L24="Empata",1,0))) -> 0 | S24: https://github.com/jfjelstul/worldcup
A25: M-2018-20 | B25: 2018 | C25: Fase de grupos | D25: B | E25: 2 | F25: 43271 | G25: Iran | H25: Spain | I25: 0 | J25: 1 | K25: =IF(OR(I25="",J25=""),"",I25&"-"&J25) -> 0-1 | L25: =IF(OR(I25="",J25=""),"",IF(I25>J25,"Gana",IF(I25=J25,"Empata","Pierde"))) -> Pierde | M25: =FALSE() -> FALSE | N25: =FALSE() -> FALSE | O25: =IF(OR(I25="",J25=""),"",I25+J25) -> 1 | P25: =IF(OR(I25="",J25=""),"",I25-J25) -> -1 | Q25: =IF(L25="","",IF(L25="Gana",3,IF(L25="Empata",1,0))) -> 0 | R25: =IF(L25="","",IF(L25="Pierde",3,IF(L25="Empata",1,0))) -> 3 | S25: https://github.com/jfjelstul/worldcup
A26: M-2018-21 | B26: 2018 | C26: Fase de grupos | D26: C | E26: 2 | F26: 43272 | G26: Denmark | H26: Australia | I26: 1 | J26: 1 | K26: =IF(OR(I26="",J26=""),"",I26&"-"&J26) -> 1-1 | L26: =IF(OR(I26="",J26=""),"",IF(I26>J26,"Gana",IF(I26=J26,"Empata","Pierde"))) -> Empata | M26: =FALSE() -> FALSE | N26: =FALSE() -> FALSE | O26: =IF(OR(I26="",J26=""),"",I26+J26) -> 2 | P26: =IF(OR(I26="",J26=""),"",I26-J26) -> 0 | Q26: =IF(L26="","",IF(L26="Gana",3,IF(L26="Empata",1,0))) -> 1 | R26: =IF(L26="","",IF(L26="Pierde",3,IF(L26="Empata",1,0))) -> 1 | S26: https://github.com/jfjelstul/worldcup
A27: M-2018-22 | B27: 2018 | C27: Fase de grupos | D27: C | E27: 2 | F27: 43272 | G27: France | H27: Peru | I27: 1 | J27: 0 | K27: =IF(OR(I27="",J27=""),"",I27&"-"&J27) -> 1-0 | L27: =IF(OR(I27="",J27=""),"",IF(I27>J27,"Gana",IF(I27=J27,"Empata","Pierde"))) -> Gana | M27: =FALSE() -> FALSE | N27: =FALSE() -> FALSE | O27: =IF(OR(I27="",J27=""),"",I27+J27) -> 1 | P27: =IF(OR(I27="",J27=""),"",I27-J27) -> 1 | Q27: =IF(L27="","",IF(L27="Gana",3,IF(L27="Empata",1,0))) -> 3 | R27: =IF(L27="","",IF(L27="Pierde",3,IF(L27="Empata",1,0))) -> 0 | S27: https://github.com/jfjelstul/worldcup
A28: M-2018-23 | B28: 2018 | C28: Fase de grupos | D28: D | E28: 2 | F28: 43272 | G28: Argentina | H28: Croatia | I28: 0 | J28: 3 | K28: =IF(OR(I28="",J28=""),"",I28&"-"&J28) -> 0-3 | L28: =IF(OR(I28="",J28=""),"",IF(I28>J28,"Gana",IF(I28=J28,"Empata","Pierde"))) -> Pierde | M28: =FALSE() -> FALSE | N28: =FALSE() -> FALSE | O28: =IF(OR(I28="",J28=""),"",I28+J28) -> 3 | P28: =IF(OR(I28="",J28=""),"",I28-J28) -> -3 | Q28: =IF(L28="","",IF(L28="Gana",3,IF(L28="Empata",1,0))) -> 0 | R28: =IF(L28="","",IF(L28="Pierde",3,IF(L28="Empata",1,0))) -> 3 | S28: https://github.com/jfjelstul/worldcup
A29: M-2018-24 | B29: 2018 | C29: Fase de grupos | D29: E | E29: 2 | F29: 43273 | G29: Brazil | H29: Costa Rica | I29: 2 | J29: 0 | K29: =IF(OR(I29="",J29=""),"",I29&"-"&J29) -> 2-0 | L29: =IF(OR(I29="",J29=""),"",IF(I29>J29,"Gana",IF(I29=J29,"Empata","Pierde"))) -> Gana | M29: =FALSE() -> FALSE | N29: =FALSE() -> FALSE | O29: =IF(OR(I29="",J29=""),"",I29+J29) -> 2 | P29: =IF(OR(I29="",J29=""),"",I29-J29) -> 2 | Q29: =IF(L29="","",IF(L29="Gana",3,IF(L29="Empata",1,0))) -> 3 | R29: =IF(L29="","",IF(L29="Pierde",3,IF(L29="Empata",1,0))) -> 0 | S29: https://github.com/jfjelstul/worldcup
A30: M-2018-25 | B30: 2018 | C30: Fase de grupos | D30: D | E30: 2 | F30: 43273 | G30: Nigeria | H30: Iceland | I30: 2 | J30: 0 | K30: =IF(OR(I30="",J30=""),"",I30&"-"&J30) -> 2-0 | L30: =IF(OR(I30="",J30=""),"",IF(I30>J30,"Gana",IF(I30=J30,"Empata","Pierde"))) -> Gana | M30: =FALSE() -> FALSE | N30: =FALSE() -> FALSE | O30: =IF(OR(I30="",J30=""),"",I30+J30) -> 2 | P30: =IF(OR(I30="",J30=""),"",I30-J30) -> 2 | Q30: =IF(L30="","",IF(L30="Gana",3,IF(L30="Empata",1,0))) -> 3 | R30: =IF(L30="","",IF(L30="Pierde",3,IF(L30="Empata",1,0))) -> 0 | S30: https://github.com/jfjelstul/worldcup
A31: M-2018-26 | B31: 2018 | C31: Fase de grupos | D31: E | E31: 2 | F31: 43273 | G31: Serbia | H31: Switzerland | I31: 1 | J31: 2 | K31: =IF(OR(I31="",J31=""),"",I31&"-"&J31) -> 1-2 | L31: =IF(OR(I31="",J31=""),"",IF(I31>J31,"Gana",IF(I31=J31,"Empata","Pierde"))) -> Pierde | M31: =FALSE() -> FALSE | N31: =FALSE() -> FALSE | O31: =IF(OR(I31="",J31=""),"",I31+J31) -> 3 | P31: =IF(OR(I31="",J31=""),"",I31-J31) -> -1 | Q31: =IF(L31="","",IF(L31="Gana",3,IF(L31="Empata",1,0))) -> 0 | R31: =IF(L31="","",IF(L31="Pierde",3,IF(L31="Empata",1,0))) -> 3 | S31: https://github.com/jfjelstul/worldcup
A32: M-2018-27 | B32: 2018 | C32: Fase de grupos | D32: G | E32: 2 | F32: 43274 | G32: Belgium | H32: Tunisia | I32: 5 | J32: 2 | K32: =IF(OR(I32="",J32=""),"",I32&"-"&J32) -> 5-2 | L32: =IF(OR(I32="",J32=""),"",IF(I32>J32,"Gana",IF(I32=J32,"Empata","Pierde"))) -> Gana | M32: =FALSE() -> FALSE | N32: =FALSE() -> FALSE | O32: =IF(OR(I32="",J32=""),"",I32+J32) -> 7 | P32: =IF(OR(I32="",J32=""),"",I32-J32) -> 3 | Q32: =IF(L32="","",IF(L32="Gana",3,IF(L32="Empata",1,0))) -> 3 | R32: =IF(L32="","",IF(L32="Pierde",3,IF(L32="Empata",1,0))) -> 0 | S32: https://github.com/jfjelstul/worldcup
A33: M-2018-28 | B33: 2018 | C33: Fase de grupos | D33: F | E33: 2 | F33: 43274 | G33: South Korea | H33: Mexico | I33: 1 | J33: 2 | K33: =IF(OR(I33="",J33=""),"",I33&"-"&J33) -> 1-2 | L33: =IF(OR(I33="",J33=""),"",IF(I33>J33,"Gana",IF(I33=J33,"Empata","Pierde"))) -> Pierde | M33: =FALSE() -> FALSE | N33: =FALSE() -> FALSE | O33: =IF(OR(I33="",J33=""),"",I33+J33) -> 3 | P33: =IF(OR(I33="",J33=""),"",I33-J33) -> -1 | Q33: =IF(L33="","",IF(L33="Gana",3,IF(L33="Empata",1,0))) -> 0 | R33: =IF(L33="","",IF(L33="Pierde",3,IF(L33="Empata",1,0))) -> 3 | S33: https://github.com/jfjelstul/worldcup
A34: M-2018-29 | B34: 2018 | C34: Fase de grupos | D34: F | E34: 2 | F34: 43274 | G34: Germany | H34: Sweden | I34: 2 | J34: 1 | K34: =IF(OR(I34="",J34=""),"",I34&"-"&J34) -> 2-1 | L34: =IF(OR(I34="",J34=""),"",IF(I34>J34,"Gana",IF(I34=J34,"Empata","Pierde"))) -> Gana | M34: =FALSE() -> FALSE | N34: =FALSE() -> FALSE | O34: =IF(OR(I34="",J34=""),"",I34+J34) -> 3 | P34: =IF(OR(I34="",J34=""),"",I34-J34) -> 1 | Q34: =IF(L34="","",IF(L34="Gana",3,IF(L34="Empata",1,0))) -> 3 | R34: =IF(L34="","",IF(L34="Pierde",3,IF(L34="Empata",1,0))) -> 0 | S34: https://github.com/jfjelstul/worldcup
... A38: M-2018-33 | B38: 2018 | C38: Fase de grupos | D38: A | E38: 3 | F38: 43276 | G38: Saudi Arabia | H38: Egypt | I38: 2 | J38: 1 | K38: =IF(OR(I38="",J38=""),"",I38&"-"&J38) -> 2-1 | L38: =IF(OR(I38="",J38=""),"",IF(I38>J38,"Gana",IF(I38=J38,"Empata","Pierde"))) -> Gana | M38: =FALSE() -> FALSE | N38: =FALSE() -> FALSE | O38: =IF(OR(I38="",J38=""),"",I38+J38) -> 3 | P38: =IF(OR(I38="",J38=""),"",I38-J38) -> 1 | Q38: =IF(L38="","",IF(L38="Gana",3,IF(L38="Empata",1,0))) -> 3 | R38: =IF(L38="","",IF(L38="Pierde",3,IF(L38="Empata",1,0))) -> 0 | S38: https://github.com/jfjelstul/worldcup
A39: M-2018-34 | B39: 2018 | C39: Fase de grupos | D39: A | E39: 3 | F39: 43276 | G39: Uruguay | H39: Russia | I39: 3 | J39: 0 | K39: =IF(OR(I39="",J39=""),"",I39&"-"&J39) -> 3-0 | L39: =IF(OR(I39="",J39=""),"",IF(I39>J39,"Gana",IF(I39=J39,"Empata","Pierde"))) -> Gana | M39: =FALSE() -> FALSE | N39: =TRUE() -> TRUE | O39: =IF(OR(I39="",J39=""),"",I39+J39) -> 3 | P39: =IF(OR(I39="",J39=""),"",I39-J39) -> 3 | Q39: =IF(L39="","",IF(L39="Gana",3,IF(L39="Empata",1,0))) -> 3 | R39: =IF(L39="","",IF(L39="Pierde",3,IF(L39="Empata",1,0))) -> 0 | S39: https://github.com/jfjelstul/worldcup
A40: M-2018-35 | B40: 2018 | C40: Fase de grupos | D40: B | E40: 3 | F40: 43276 | G40: Spain | H40: Morocco | I40: 2 | J40: 2 | K40: =IF(OR(I40="",J40=""),"",I40&"-"&J40) -> 2-2 | L40: =IF(OR(I40="",J40=""),"",IF(I40>J40,"Gana",IF(I40=J40,"Empata","Pierde"))) -> Empata | M40: =FALSE() -> FALSE | N40: =FALSE() -> FALSE | O40: =IF(OR(I40="",J40=""),"",I40+J40) -> 4 | P40: =IF(OR(I40="",J40=""),"",I40-J40) -> 0 | Q40: =IF(L40="","",IF(L40="Gana",3,IF(L40="Empata",1,0))) -> 1 | R40: =IF(L40="","",IF(L40="Pierde",3,IF(L40="Empata",1,0))) -> 1 | S40: https://github.com/jfjelstul/worldcup
A41: M-2018-36 | B41: 2018 | C41: Fase de grupos | D41: B | E41: 3 | F41: 43276 | G41: Iran | H41: Portugal | I41: 1 | J41: 1 | K41: =IF(OR(I41="",J41=""),"",I41&"-"&J41) -> 1-1 | L41: =IF(OR(I41="",J41=""),"",IF(I41>J41,"Gana",IF(I41=J41,"Empata","Pierde"))) -> Empata | M41: =FALSE() -> FALSE | N41: =FALSE() -> FALSE | O41: =IF(OR(I41="",J41=""),"",I41+J41) -> 2 | P41: =IF(OR(I41="",J41=""),"",I41-J41) -> 0 | Q41: =IF(L41="","",IF(L41="Gana",3,IF(L41="Empata",1,0))) -> 1 | R41: =IF(L41="","",IF(L41="Pierde",3,IF(L41="Empata",1,0))) -> 1 | S41: https://github.com/jfjelstul/worldcup
A42: M-2018-37 | B42: 2018 | C42: Fase de grupos | D42: C | E42: 3 | F42: 43277 | G42: Australia | H42: Peru | I42: 0 | J42: 2 | K42: =IF(OR(I42="",J42=""),"",I42&"-"&J42) -> 0-2 | L42: =IF(OR(I42="",J42=""),"",IF(I42>J42,"Gana",IF(I42=J42,"Empata","Pierde"))) -> Pierde | M42: =FALSE() -> FALSE | N42: =FALSE() -> FALSE | O42: =IF(OR(I42="",J42=""),"",I42+J42) -> 2 | P42: =IF(OR(I42="",J42=""),"",I42-J42) -> -2 | Q42: =IF(L42="","",IF(L42="Gana",3,IF(L42="Empata",1,0))) -> 0 | R42: =IF(L42="","",IF(L42="Pierde",3,IF(L42="Empata",1,0))) -> 3 | S42: https://github.com/jfjelstul/worldcup
A43: M-2018-38 | B43: 2018 | C43: Fase de grupos | D43: C | E43: 3 | F43: 43277 | G43: Denmark | H43: France | I43: 0 | J43: 0 | K43: =IF(OR(I43="",J43=""),"",I43&"-"&J43) -> 0-0 | L43: =IF(OR(I43="",J43=""),"",IF(I43>J43,"Gana",IF(I43=J43,"Empata","Pierde"))) -> Empata | M43: =FALSE() -> FALSE | N43: =FALSE() -> FALSE | O43: =IF(OR(I43="",J43=""),"",I43+J43) -> 0 | P43: =IF(OR(I43="",J43=""),"",I43-J43) -> 0 | Q43: =IF(L43="","",IF(L43="Gana",3,IF(L43="Empata",1,0))) -> 1 | R43: =IF(L43="","",IF(L43="Pierde",3,IF(L43="Empata",1,0))) -> 1 | S43: https://github.com/jfjelstul/worldcup
